A nice [[S3]] tool, available on [[Debian]], written by Michal Lugvig.

I just got this error:

<pre>
!!!!!!!!!!!!!!!!!!!!!!!!!!!!!!!!!!!!!!!!!
    An unexpected error has occurred.
  Please report the following lines to:
  s3tools-general@lists.sourceforge.net
!!!!!!!!!!!!!!!!!!!!!!!!!!!!!!!!!!!!!!!!!

S3cmd:  0.9.8.3
Python: 2.5.2 (r252:60911, Jan 24 2010, 17:44:40)  [GCC 4.3.2]

Traceback (most recent call last):
  File "/usr/bin/s3cmd", line 1040, in <module>
    main()
  File "/usr/bin/s3cmd", line 1020, in main
    cmd_func(args)
  File "/usr/bin/s3cmd", line 627, in cmd_sync
    return cmd_sync_local2remote(src, dst)
  File "/usr/bin/s3cmd", line 599, in cmd_sync_local2remote
    response = s3.object_put_uri(src, uri, attr_header)
  File "/usr/lib/python2.5/site-packages/S3/S3.py", line 195, in object_put_uri
    return self.object_put(filename, uri.bucket(), uri.object(), extra_headers)
  File "/usr/lib/python2.5/site-packages/S3/S3.py", line 175, in object_put
    response = self.send_file(request, file)
  File "/usr/lib/python2.5/site-packages/S3/S3.py", line 328, in send_file
    conn.connect()
  File "/usr/lib/python2.5/httplib.py", line 683, in connect
    raise socket.error, msg
error: (110, 'Connection timed out')

!!!!!!!!!!!!!!!!!!!!!!!!!!!!!!!!!!!!!!!!!
    An unexpected error has occurred.
    Please report the above lines to:
  s3tools-general@lists.sourceforge.net
!!!!!!!!!!!!!!!!!!!!!!!!!!!!!!!!!!!!!!!!!
</pre>

